### 捕获错误

采用try...catch...finally... 的风格
```js
try {
    ...
} catch (e) {
    ...
}
/********************************/
try {
    ...
} finally {
    ...
}
/********************************/
try {
    ...
} catch (e) {
    ...
} finally {
    ...
}
```

----------------------------------------------------

### 错误类型

JavaScript有一个标准的Error对象表示错误

还有从Error派生的TypeError、ReferenceError、SyntaxError、RangeError等错误对象

----------------------------------------------------

### 抛出错误

程序可以使用`throw语句`主动抛出一个错误，让执行流程直接跳转到catch块

```js
var r, n, s;

try {
  s = prompt('请输入一个数字');
  n = parseInt(s);
  if (isNaN(n)) {
    throw new Error('输入错误');
}
// 计算平方:
r = n * n;
  console.log(n + ' * ' + n + ' = ' + r);
} catch (e) {
  console.log('出错了：' + e);
}
```

实际上，JavaScript允许抛出任意对象，包括数字、字符串，但最好还是抛出一个Error对象

----------------------------------------------------

### 错误传播

如果在一个函数内部发生了错误，它自身没有捕获，错误就会被抛到外层调用函数，如果外层函数也没有捕获，该错误会一直沿着函数调用链向上抛出，直到被JavaScript引擎捕获，代码终止执

所以，我们不必在每一个函数内部捕获错误，只需要在合适的地方来个统一捕获，一网打尽